ERROR 2025-07-31 09:42:17,302 log 1748 11416 Internal Server Error: /api/accounts/alerts/
Traceback (most recent call last):
  File "C:\Users\azizo\Desktop\Pathnio1\backend\env\Lib\site-packages\django\db\backends\utils.py", line 105, in _execute
    return self.cursor.execute(sql, params)
           ~~~~~~~~~~~~~~~~~~~^^^^^^^^^^^^^
  File "C:\Users\azizo\Desktop\Pathnio1\backend\env\Lib\site-packages\django\db\backends\sqlite3\base.py", line 360, in execute
    return super().execute(query, params)
           ~~~~~~~~~~~~~~~^^^^^^^^^^^^^^^
sqlite3.OperationalError: no such table: accounts_alert

The above exception was the direct cause of the following exception:

Traceback (most recent call last):
  File "C:\Users\azizo\Desktop\Pathnio1\backend\env\Lib\site-packages\django\core\handlers\exception.py", line 55, in inner
    response = get_response(request)
  File "C:\Users\azizo\Desktop\Pathnio1\backend\env\Lib\site-packages\django\core\handlers\base.py", line 197, in _get_response
    response = wrapped_callback(request, *callback_args, **callback_kwargs)
  File "C:\Users\azizo\Desktop\Pathnio1\backend\env\Lib\site-packages\django\views\decorators\csrf.py", line 65, in _view_wrapper
    return view_func(request, *args, **kwargs)
  File "C:\Users\azizo\Desktop\Pathnio1\backend\env\Lib\site-packages\django\views\generic\base.py", line 105, in view
    return self.dispatch(request, *args, **kwargs)
           ~~~~~~~~~~~~~^^^^^^^^^^^^^^^^^^^^^^^^^^
  File "C:\Users\azizo\Desktop\Pathnio1\backend\env\Lib\site-packages\rest_framework\views.py", line 515, in dispatch
    response = self.handle_exception(exc)
  File "C:\Users\azizo\Desktop\Pathnio1\backend\env\Lib\site-packages\rest_framework\views.py", line 475, in handle_exception
    self.raise_uncaught_exception(exc)
    ~~~~~~~~~~~~~~~~~~~~~~~~~~~~~^^^^^
  File "C:\Users\azizo\Desktop\Pathnio1\backend\env\Lib\site-packages\rest_framework\views.py", line 486, in raise_uncaught_exception
    raise exc
  File "C:\Users\azizo\Desktop\Pathnio1\backend\env\Lib\site-packages\rest_framework\views.py", line 512, in dispatch
    response = handler(request, *args, **kwargs)
  File "C:\Users\azizo\Desktop\Pathnio1\backend\accounts\views.py", line 1202, in get
    return Response(serializer.data)
                    ^^^^^^^^^^^^^^^
  File "C:\Users\azizo\Desktop\Pathnio1\backend\env\Lib\site-packages\rest_framework\serializers.py", line 797, in data
    ret = super().data
          ^^^^^^^^^^^^
  File "C:\Users\azizo\Desktop\Pathnio1\backend\env\Lib\site-packages\rest_framework\serializers.py", line 251, in data
    self._data = self.to_representation(self.instance)
                 ~~~~~~~~~~~~~~~~~~~~~~^^^^^^^^^^^^^^^
  File "C:\Users\azizo\Desktop\Pathnio1\backend\env\Lib\site-packages\rest_framework\serializers.py", line 716, in to_representation
    self.child.to_representation(item) for item in iterable
                                                   ^^^^^^^^
  File "C:\Users\azizo\Desktop\Pathnio1\backend\env\Lib\site-packages\django\db\models\query.py", line 384, in __iter__
    self._fetch_all()
    ~~~~~~~~~~~~~~~^^
  File "C:\Users\azizo\Desktop\Pathnio1\backend\env\Lib\site-packages\django\db\models\query.py", line 1949, in _fetch_all
    self._result_cache = list(self._iterable_class(self))
                         ~~~~^^^^^^^^^^^^^^^^^^^^^^^^^^^^
  File "C:\Users\azizo\Desktop\Pathnio1\backend\env\Lib\site-packages\django\db\models\query.py", line 91, in __iter__
    results = compiler.execute_sql(
        chunked_fetch=self.chunked_fetch, chunk_size=self.chunk_size
    )
  File "C:\Users\azizo\Desktop\Pathnio1\backend\env\Lib\site-packages\django\db\models\sql\compiler.py", line 1623, in execute_sql
    cursor.execute(sql, params)
    ~~~~~~~~~~~~~~^^^^^^^^^^^^^
  File "C:\Users\azizo\Desktop\Pathnio1\backend\env\Lib\site-packages\django\db\backends\utils.py", line 122, in execute
    return super().execute(sql, params)
           ~~~~~~~~~~~~~~~^^^^^^^^^^^^^
  File "C:\Users\azizo\Desktop\Pathnio1\backend\env\Lib\site-packages\django\db\backends\utils.py", line 79, in execute
    return self._execute_with_wrappers(
           ~~~~~~~~~~~~~~~~~~~~~~~~~~~^
        sql, params, many=False, executor=self._execute
        ^^^^^^^^^^^^^^^^^^^^^^^^^^^^^^^^^^^^^^^^^^^^^^^
    )
    ^
  File "C:\Users\azizo\Desktop\Pathnio1\backend\env\Lib\site-packages\django\db\backends\utils.py", line 92, in _execute_with_wrappers
    return executor(sql, params, many, context)
  File "C:\Users\azizo\Desktop\Pathnio1\backend\env\Lib\site-packages\django\db\backends\utils.py", line 100, in _execute
    with self.db.wrap_database_errors:
         ^^^^^^^^^^^^^^^^^^^^^^^^^^^^
  File "C:\Users\azizo\Desktop\Pathnio1\backend\env\Lib\site-packages\django\db\utils.py", line 91, in __exit__
    raise dj_exc_value.with_traceback(traceback) from exc_value
  File "C:\Users\azizo\Desktop\Pathnio1\backend\env\Lib\site-packages\django\db\backends\utils.py", line 105, in _execute
    return self.cursor.execute(sql, params)
           ~~~~~~~~~~~~~~~~~~~^^^^^^^^^^^^^
  File "C:\Users\azizo\Desktop\Pathnio1\backend\env\Lib\site-packages\django\db\backends\sqlite3\base.py", line 360, in execute
    return super().execute(query, params)
           ~~~~~~~~~~~~~~~^^^^^^^^^^^^^^^
django.db.utils.OperationalError: no such table: accounts_alert
ERROR 2025-07-31 09:42:17,339 basehttp 1748 11416 "GET /api/accounts/alerts/ HTTP/1.1" 500 179825
ERROR 2025-07-31 09:42:17,578 log 1748 15640 Internal Server Error: /api/accounts/alerts/
Traceback (most recent call last):
  File "C:\Users\azizo\Desktop\Pathnio1\backend\env\Lib\site-packages\django\db\backends\utils.py", line 105, in _execute
    return self.cursor.execute(sql, params)
           ~~~~~~~~~~~~~~~~~~~^^^^^^^^^^^^^
  File "C:\Users\azizo\Desktop\Pathnio1\backend\env\Lib\site-packages\django\db\backends\sqlite3\base.py", line 360, in execute
    return super().execute(query, params)
           ~~~~~~~~~~~~~~~^^^^^^^^^^^^^^^
sqlite3.OperationalError: no such table: accounts_alert

The above exception was the direct cause of the following exception:

Traceback (most recent call last):
  File "C:\Users\azizo\Desktop\Pathnio1\backend\env\Lib\site-packages\django\core\handlers\exception.py", line 55, in inner
    response = get_response(request)
  File "C:\Users\azizo\Desktop\Pathnio1\backend\env\Lib\site-packages\django\core\handlers\base.py", line 197, in _get_response
    response = wrapped_callback(request, *callback_args, **callback_kwargs)
  File "C:\Users\azizo\Desktop\Pathnio1\backend\env\Lib\site-packages\django\views\decorators\csrf.py", line 65, in _view_wrapper
    return view_func(request, *args, **kwargs)
  File "C:\Users\azizo\Desktop\Pathnio1\backend\env\Lib\site-packages\django\views\generic\base.py", line 105, in view
    return self.dispatch(request, *args, **kwargs)
           ~~~~~~~~~~~~~^^^^^^^^^^^^^^^^^^^^^^^^^^
  File "C:\Users\azizo\Desktop\Pathnio1\backend\env\Lib\site-packages\rest_framework\views.py", line 515, in dispatch
    response = self.handle_exception(exc)
  File "C:\Users\azizo\Desktop\Pathnio1\backend\env\Lib\site-packages\rest_framework\views.py", line 475, in handle_exception
    self.raise_uncaught_exception(exc)
    ~~~~~~~~~~~~~~~~~~~~~~~~~~~~~^^^^^
  File "C:\Users\azizo\Desktop\Pathnio1\backend\env\Lib\site-packages\rest_framework\views.py", line 486, in raise_uncaught_exception
    raise exc
  File "C:\Users\azizo\Desktop\Pathnio1\backend\env\Lib\site-packages\rest_framework\views.py", line 512, in dispatch
    response = handler(request, *args, **kwargs)
  File "C:\Users\azizo\Desktop\Pathnio1\backend\accounts\views.py", line 1202, in get
    return Response(serializer.data)
                    ^^^^^^^^^^^^^^^
  File "C:\Users\azizo\Desktop\Pathnio1\backend\env\Lib\site-packages\rest_framework\serializers.py", line 797, in data
    ret = super().data
          ^^^^^^^^^^^^
  File "C:\Users\azizo\Desktop\Pathnio1\backend\env\Lib\site-packages\rest_framework\serializers.py", line 251, in data
    self._data = self.to_representation(self.instance)
                 ~~~~~~~~~~~~~~~~~~~~~~^^^^^^^^^^^^^^^
  File "C:\Users\azizo\Desktop\Pathnio1\backend\env\Lib\site-packages\rest_framework\serializers.py", line 716, in to_representation
    self.child.to_representation(item) for item in iterable
                                                   ^^^^^^^^
  File "C:\Users\azizo\Desktop\Pathnio1\backend\env\Lib\site-packages\django\db\models\query.py", line 384, in __iter__
    self._fetch_all()
    ~~~~~~~~~~~~~~~^^
  File "C:\Users\azizo\Desktop\Pathnio1\backend\env\Lib\site-packages\django\db\models\query.py", line 1949, in _fetch_all
    self._result_cache = list(self._iterable_class(self))
                         ~~~~^^^^^^^^^^^^^^^^^^^^^^^^^^^^
  File "C:\Users\azizo\Desktop\Pathnio1\backend\env\Lib\site-packages\django\db\models\query.py", line 91, in __iter__
    results = compiler.execute_sql(
        chunked_fetch=self.chunked_fetch, chunk_size=self.chunk_size
    )
  File "C:\Users\azizo\Desktop\Pathnio1\backend\env\Lib\site-packages\django\db\models\sql\compiler.py", line 1623, in execute_sql
    cursor.execute(sql, params)
    ~~~~~~~~~~~~~~^^^^^^^^^^^^^
  File "C:\Users\azizo\Desktop\Pathnio1\backend\env\Lib\site-packages\django\db\backends\utils.py", line 122, in execute
    return super().execute(sql, params)
           ~~~~~~~~~~~~~~~^^^^^^^^^^^^^
  File "C:\Users\azizo\Desktop\Pathnio1\backend\env\Lib\site-packages\django\db\backends\utils.py", line 79, in execute
    return self._execute_with_wrappers(
           ~~~~~~~~~~~~~~~~~~~~~~~~~~~^
        sql, params, many=False, executor=self._execute
        ^^^^^^^^^^^^^^^^^^^^^^^^^^^^^^^^^^^^^^^^^^^^^^^
    )
    ^
  File "C:\Users\azizo\Desktop\Pathnio1\backend\env\Lib\site-packages\django\db\backends\utils.py", line 92, in _execute_with_wrappers
    return executor(sql, params, many, context)
  File "C:\Users\azizo\Desktop\Pathnio1\backend\env\Lib\site-packages\django\db\backends\utils.py", line 100, in _execute
    with self.db.wrap_database_errors:
         ^^^^^^^^^^^^^^^^^^^^^^^^^^^^
  File "C:\Users\azizo\Desktop\Pathnio1\backend\env\Lib\site-packages\django\db\utils.py", line 91, in __exit__
    raise dj_exc_value.with_traceback(traceback) from exc_value
  File "C:\Users\azizo\Desktop\Pathnio1\backend\env\Lib\site-packages\django\db\backends\utils.py", line 105, in _execute
    return self.cursor.execute(sql, params)
           ~~~~~~~~~~~~~~~~~~~^^^^^^^^^^^^^
  File "C:\Users\azizo\Desktop\Pathnio1\backend\env\Lib\site-packages\django\db\backends\sqlite3\base.py", line 360, in execute
    return super().execute(query, params)
           ~~~~~~~~~~~~~~~^^^^^^^^^^^^^^^
django.db.utils.OperationalError: no such table: accounts_alert
ERROR 2025-07-31 09:42:17,603 basehttp 1748 15640 "GET /api/accounts/alerts/ HTTP/1.1" 500 179825
ERROR 2025-07-31 09:42:44,458 log 1748 25428 Internal Server Error: /api/accounts/users/all/
Traceback (most recent call last):
  File "C:\Users\azizo\Desktop\Pathnio1\backend\env\Lib\site-packages\django\db\models\fields\related_descriptors.py", line 516, in __get__
    rel_obj = self.related.get_cached_value(instance)
  File "C:\Users\azizo\Desktop\Pathnio1\backend\env\Lib\site-packages\django\db\models\fields\mixins.py", line 37, in get_cached_value
    return instance._state.fields_cache[self.cache_name]
           ~~~~~~~~~~~~~~~~~~~~~~~~~~~~^^^^^^^^^^^^^^^^^
KeyError: 'profile'

During handling of the above exception, another exception occurred:

Traceback (most recent call last):
  File "C:\Users\azizo\Desktop\Pathnio1\backend\env\Lib\site-packages\django\db\backends\utils.py", line 105, in _execute
    return self.cursor.execute(sql, params)
           ~~~~~~~~~~~~~~~~~~~^^^^^^^^^^^^^
  File "C:\Users\azizo\Desktop\Pathnio1\backend\env\Lib\site-packages\django\db\backends\sqlite3\base.py", line 360, in execute
    return super().execute(query, params)
           ~~~~~~~~~~~~~~~^^^^^^^^^^^^^^^
sqlite3.OperationalError: no such table: accounts_profile

The above exception was the direct cause of the following exception:

Traceback (most recent call last):
  File "C:\Users\azizo\Desktop\Pathnio1\backend\env\Lib\site-packages\django\core\handlers\exception.py", line 55, in inner
    response = get_response(request)
  File "C:\Users\azizo\Desktop\Pathnio1\backend\env\Lib\site-packages\django\core\handlers\base.py", line 197, in _get_response
    response = wrapped_callback(request, *callback_args, **callback_kwargs)
  File "C:\Users\azizo\Desktop\Pathnio1\backend\env\Lib\site-packages\django\views\decorators\csrf.py", line 65, in _view_wrapper
    return view_func(request, *args, **kwargs)
  File "C:\Users\azizo\Desktop\Pathnio1\backend\env\Lib\site-packages\django\views\generic\base.py", line 105, in view
    return self.dispatch(request, *args, **kwargs)
           ~~~~~~~~~~~~~^^^^^^^^^^^^^^^^^^^^^^^^^^
  File "C:\Users\azizo\Desktop\Pathnio1\backend\env\Lib\site-packages\rest_framework\views.py", line 515, in dispatch
    response = self.handle_exception(exc)
  File "C:\Users\azizo\Desktop\Pathnio1\backend\env\Lib\site-packages\rest_framework\views.py", line 475, in handle_exception
    self.raise_uncaught_exception(exc)
    ~~~~~~~~~~~~~~~~~~~~~~~~~~~~~^^^^^
  File "C:\Users\azizo\Desktop\Pathnio1\backend\env\Lib\site-packages\rest_framework\views.py", line 486, in raise_uncaught_exception
    raise exc
  File "C:\Users\azizo\Desktop\Pathnio1\backend\env\Lib\site-packages\rest_framework\views.py", line 512, in dispatch
    response = handler(request, *args, **kwargs)
  File "C:\Users\azizo\Desktop\Pathnio1\backend\accounts\views.py", line 810, in get
    'profile_photo': u.profile.profile_photo.url if hasattr(u, 'profile') and u.profile.profile_photo else (company.profile_photo.url if company and company.profile_photo else None),
                                                    ~~~~~~~^^^^^^^^^^^^^^
  File "C:\Users\azizo\Desktop\Pathnio1\backend\env\Lib\site-packages\django\db\models\fields\related_descriptors.py", line 523, in __get__
    rel_obj = self.get_queryset(instance=instance).get(**filter_args)
  File "C:\Users\azizo\Desktop\Pathnio1\backend\env\Lib\site-packages\django\db\models\query.py", line 629, in get
    num = len(clone)
  File "C:\Users\azizo\Desktop\Pathnio1\backend\env\Lib\site-packages\django\db\models\query.py", line 366, in __len__
    self._fetch_all()
    ~~~~~~~~~~~~~~~^^
  File "C:\Users\azizo\Desktop\Pathnio1\backend\env\Lib\site-packages\django\db\models\query.py", line 1949, in _fetch_all
    self._result_cache = list(self._iterable_class(self))
                         ~~~~^^^^^^^^^^^^^^^^^^^^^^^^^^^^
  File "C:\Users\azizo\Desktop\Pathnio1\backend\env\Lib\site-packages\django\db\models\query.py", line 91, in __iter__
    results = compiler.execute_sql(
        chunked_fetch=self.chunked_fetch, chunk_size=self.chunk_size
    )
  File "C:\Users\azizo\Desktop\Pathnio1\backend\env\Lib\site-packages\django\db\models\sql\compiler.py", line 1623, in execute_sql
    cursor.execute(sql, params)
    ~~~~~~~~~~~~~~^^^^^^^^^^^^^
  File "C:\Users\azizo\Desktop\Pathnio1\backend\env\Lib\site-packages\django\db\backends\utils.py", line 122, in execute
    return super().execute(sql, params)
           ~~~~~~~~~~~~~~~^^^^^^^^^^^^^
  File "C:\Users\azizo\Desktop\Pathnio1\backend\env\Lib\site-packages\django\db\backends\utils.py", line 79, in execute
    return self._execute_with_wrappers(
           ~~~~~~~~~~~~~~~~~~~~~~~~~~~^
        sql, params, many=False, executor=self._execute
        ^^^^^^^^^^^^^^^^^^^^^^^^^^^^^^^^^^^^^^^^^^^^^^^
    )
    ^
  File "C:\Users\azizo\Desktop\Pathnio1\backend\env\Lib\site-packages\django\db\backends\utils.py", line 92, in _execute_with_wrappers
    return executor(sql, params, many, context)
  File "C:\Users\azizo\Desktop\Pathnio1\backend\env\Lib\site-packages\django\db\backends\utils.py", line 100, in _execute
    with self.db.wrap_database_errors:
         ^^^^^^^^^^^^^^^^^^^^^^^^^^^^
  File "C:\Users\azizo\Desktop\Pathnio1\backend\env\Lib\site-packages\django\db\utils.py", line 91, in __exit__
    raise dj_exc_value.with_traceback(traceback) from exc_value
  File "C:\Users\azizo\Desktop\Pathnio1\backend\env\Lib\site-packages\django\db\backends\utils.py", line 105, in _execute
    return self.cursor.execute(sql, params)
           ~~~~~~~~~~~~~~~~~~~^^^^^^^^^^^^^
  File "C:\Users\azizo\Desktop\Pathnio1\backend\env\Lib\site-packages\django\db\backends\sqlite3\base.py", line 360, in execute
    return super().execute(query, params)
           ~~~~~~~~~~~~~~~^^^^^^^^^^^^^^^
django.db.utils.OperationalError: no such table: accounts_profile
ERROR 2025-07-31 09:42:44,510 basehttp 1748 25428 "GET /api/accounts/users/all/ HTTP/1.1" 500 183258
ERROR 2025-07-31 09:42:45,071 log 1748 13984 Internal Server Error: /api/accounts/users/all/
Traceback (most recent call last):
  File "C:\Users\azizo\Desktop\Pathnio1\backend\env\Lib\site-packages\django\db\models\fields\related_descriptors.py", line 516, in __get__
    rel_obj = self.related.get_cached_value(instance)
  File "C:\Users\azizo\Desktop\Pathnio1\backend\env\Lib\site-packages\django\db\models\fields\mixins.py", line 37, in get_cached_value
    return instance._state.fields_cache[self.cache_name]
           ~~~~~~~~~~~~~~~~~~~~~~~~~~~~^^^^^^^^^^^^^^^^^
KeyError: 'profile'

During handling of the above exception, another exception occurred:

Traceback (most recent call last):
  File "C:\Users\azizo\Desktop\Pathnio1\backend\env\Lib\site-packages\django\db\backends\utils.py", line 105, in _execute
    return self.cursor.execute(sql, params)
           ~~~~~~~~~~~~~~~~~~~^^^^^^^^^^^^^
  File "C:\Users\azizo\Desktop\Pathnio1\backend\env\Lib\site-packages\django\db\backends\sqlite3\base.py", line 360, in execute
    return super().execute(query, params)
           ~~~~~~~~~~~~~~~^^^^^^^^^^^^^^^
sqlite3.OperationalError: no such table: accounts_profile

The above exception was the direct cause of the following exception:

Traceback (most recent call last):
  File "C:\Users\azizo\Desktop\Pathnio1\backend\env\Lib\site-packages\django\core\handlers\exception.py", line 55, in inner
    response = get_response(request)
  File "C:\Users\azizo\Desktop\Pathnio1\backend\env\Lib\site-packages\django\core\handlers\base.py", line 197, in _get_response
    response = wrapped_callback(request, *callback_args, **callback_kwargs)
  File "C:\Users\azizo\Desktop\Pathnio1\backend\env\Lib\site-packages\django\views\decorators\csrf.py", line 65, in _view_wrapper
    return view_func(request, *args, **kwargs)
  File "C:\Users\azizo\Desktop\Pathnio1\backend\env\Lib\site-packages\django\views\generic\base.py", line 105, in view
    return self.dispatch(request, *args, **kwargs)
           ~~~~~~~~~~~~~^^^^^^^^^^^^^^^^^^^^^^^^^^
  File "C:\Users\azizo\Desktop\Pathnio1\backend\env\Lib\site-packages\rest_framework\views.py", line 515, in dispatch
    response = self.handle_exception(exc)
  File "C:\Users\azizo\Desktop\Pathnio1\backend\env\Lib\site-packages\rest_framework\views.py", line 475, in handle_exception
    self.raise_uncaught_exception(exc)
    ~~~~~~~~~~~~~~~~~~~~~~~~~~~~~^^^^^
  File "C:\Users\azizo\Desktop\Pathnio1\backend\env\Lib\site-packages\rest_framework\views.py", line 486, in raise_uncaught_exception
    raise exc
  File "C:\Users\azizo\Desktop\Pathnio1\backend\env\Lib\site-packages\rest_framework\views.py", line 512, in dispatch
    response = handler(request, *args, **kwargs)
  File "C:\Users\azizo\Desktop\Pathnio1\backend\accounts\views.py", line 810, in get
    'profile_photo': u.profile.profile_photo.url if hasattr(u, 'profile') and u.profile.profile_photo else (company.profile_photo.url if company and company.profile_photo else None),
                                                    ~~~~~~~^^^^^^^^^^^^^^
  File "C:\Users\azizo\Desktop\Pathnio1\backend\env\Lib\site-packages\django\db\models\fields\related_descriptors.py", line 523, in __get__
    rel_obj = self.get_queryset(instance=instance).get(**filter_args)
  File "C:\Users\azizo\Desktop\Pathnio1\backend\env\Lib\site-packages\django\db\models\query.py", line 629, in get
    num = len(clone)
  File "C:\Users\azizo\Desktop\Pathnio1\backend\env\Lib\site-packages\django\db\models\query.py", line 366, in __len__
    self._fetch_all()
    ~~~~~~~~~~~~~~~^^
  File "C:\Users\azizo\Desktop\Pathnio1\backend\env\Lib\site-packages\django\db\models\query.py", line 1949, in _fetch_all
    self._result_cache = list(self._iterable_class(self))
                         ~~~~^^^^^^^^^^^^^^^^^^^^^^^^^^^^
  File "C:\Users\azizo\Desktop\Pathnio1\backend\env\Lib\site-packages\django\db\models\query.py", line 91, in __iter__
    results = compiler.execute_sql(
        chunked_fetch=self.chunked_fetch, chunk_size=self.chunk_size
    )
  File "C:\Users\azizo\Desktop\Pathnio1\backend\env\Lib\site-packages\django\db\models\sql\compiler.py", line 1623, in execute_sql
    cursor.execute(sql, params)
    ~~~~~~~~~~~~~~^^^^^^^^^^^^^
  File "C:\Users\azizo\Desktop\Pathnio1\backend\env\Lib\site-packages\django\db\backends\utils.py", line 122, in execute
    return super().execute(sql, params)
           ~~~~~~~~~~~~~~~^^^^^^^^^^^^^
  File "C:\Users\azizo\Desktop\Pathnio1\backend\env\Lib\site-packages\django\db\backends\utils.py", line 79, in execute
    return self._execute_with_wrappers(
           ~~~~~~~~~~~~~~~~~~~~~~~~~~~^
        sql, params, many=False, executor=self._execute
        ^^^^^^^^^^^^^^^^^^^^^^^^^^^^^^^^^^^^^^^^^^^^^^^
    )
    ^
  File "C:\Users\azizo\Desktop\Pathnio1\backend\env\Lib\site-packages\django\db\backends\utils.py", line 92, in _execute_with_wrappers
    return executor(sql, params, many, context)
  File "C:\Users\azizo\Desktop\Pathnio1\backend\env\Lib\site-packages\django\db\backends\utils.py", line 100, in _execute
    with self.db.wrap_database_errors:
         ^^^^^^^^^^^^^^^^^^^^^^^^^^^^
  File "C:\Users\azizo\Desktop\Pathnio1\backend\env\Lib\site-packages\django\db\utils.py", line 91, in __exit__
    raise dj_exc_value.with_traceback(traceback) from exc_value
  File "C:\Users\azizo\Desktop\Pathnio1\backend\env\Lib\site-packages\django\db\backends\utils.py", line 105, in _execute
    return self.cursor.execute(sql, params)
           ~~~~~~~~~~~~~~~~~~~^^^^^^^^^^^^^
  File "C:\Users\azizo\Desktop\Pathnio1\backend\env\Lib\site-packages\django\db\backends\sqlite3\base.py", line 360, in execute
    return super().execute(query, params)
           ~~~~~~~~~~~~~~~^^^^^^^^^^^^^^^
django.db.utils.OperationalError: no such table: accounts_profile
ERROR 2025-07-31 09:42:45,085 basehttp 1748 13984 "GET /api/accounts/users/all/ HTTP/1.1" 500 183258
ERROR 2025-07-31 09:42:51,426 log 1748 15400 Internal Server Error: /api/accounts/users/all/
Traceback (most recent call last):
  File "C:\Users\azizo\Desktop\Pathnio1\backend\env\Lib\site-packages\django\db\models\fields\related_descriptors.py", line 516, in __get__
    rel_obj = self.related.get_cached_value(instance)
  File "C:\Users\azizo\Desktop\Pathnio1\backend\env\Lib\site-packages\django\db\models\fields\mixins.py", line 37, in get_cached_value
    return instance._state.fields_cache[self.cache_name]
           ~~~~~~~~~~~~~~~~~~~~~~~~~~~~^^^^^^^^^^^^^^^^^
KeyError: 'profile'

During handling of the above exception, another exception occurred:

Traceback (most recent call last):
  File "C:\Users\azizo\Desktop\Pathnio1\backend\env\Lib\site-packages\django\db\backends\utils.py", line 105, in _execute
    return self.cursor.execute(sql, params)
           ~~~~~~~~~~~~~~~~~~~^^^^^^^^^^^^^
  File "C:\Users\azizo\Desktop\Pathnio1\backend\env\Lib\site-packages\django\db\backends\sqlite3\base.py", line 360, in execute
    return super().execute(query, params)
           ~~~~~~~~~~~~~~~^^^^^^^^^^^^^^^
sqlite3.OperationalError: no such table: accounts_profile

The above exception was the direct cause of the following exception:

Traceback (most recent call last):
  File "C:\Users\azizo\Desktop\Pathnio1\backend\env\Lib\site-packages\django\core\handlers\exception.py", line 55, in inner
    response = get_response(request)
  File "C:\Users\azizo\Desktop\Pathnio1\backend\env\Lib\site-packages\django\core\handlers\base.py", line 197, in _get_response
    response = wrapped_callback(request, *callback_args, **callback_kwargs)
  File "C:\Users\azizo\Desktop\Pathnio1\backend\env\Lib\site-packages\django\views\decorators\csrf.py", line 65, in _view_wrapper
    return view_func(request, *args, **kwargs)
  File "C:\Users\azizo\Desktop\Pathnio1\backend\env\Lib\site-packages\django\views\generic\base.py", line 105, in view
    return self.dispatch(request, *args, **kwargs)
           ~~~~~~~~~~~~~^^^^^^^^^^^^^^^^^^^^^^^^^^
  File "C:\Users\azizo\Desktop\Pathnio1\backend\env\Lib\site-packages\rest_framework\views.py", line 515, in dispatch
    response = self.handle_exception(exc)
  File "C:\Users\azizo\Desktop\Pathnio1\backend\env\Lib\site-packages\rest_framework\views.py", line 475, in handle_exception
    self.raise_uncaught_exception(exc)
    ~~~~~~~~~~~~~~~~~~~~~~~~~~~~~^^^^^
  File "C:\Users\azizo\Desktop\Pathnio1\backend\env\Lib\site-packages\rest_framework\views.py", line 486, in raise_uncaught_exception
    raise exc
  File "C:\Users\azizo\Desktop\Pathnio1\backend\env\Lib\site-packages\rest_framework\views.py", line 512, in dispatch
    response = handler(request, *args, **kwargs)
  File "C:\Users\azizo\Desktop\Pathnio1\backend\accounts\views.py", line 810, in get
    'profile_photo': u.profile.profile_photo.url if hasattr(u, 'profile') and u.profile.profile_photo else (company.profile_photo.url if company and company.profile_photo else None),
                                                    ~~~~~~~^^^^^^^^^^^^^^
  File "C:\Users\azizo\Desktop\Pathnio1\backend\env\Lib\site-packages\django\db\models\fields\related_descriptors.py", line 523, in __get__
    rel_obj = self.get_queryset(instance=instance).get(**filter_args)
  File "C:\Users\azizo\Desktop\Pathnio1\backend\env\Lib\site-packages\django\db\models\query.py", line 629, in get
    num = len(clone)
  File "C:\Users\azizo\Desktop\Pathnio1\backend\env\Lib\site-packages\django\db\models\query.py", line 366, in __len__
    self._fetch_all()
    ~~~~~~~~~~~~~~~^^
  File "C:\Users\azizo\Desktop\Pathnio1\backend\env\Lib\site-packages\django\db\models\query.py", line 1949, in _fetch_all
    self._result_cache = list(self._iterable_class(self))
                         ~~~~^^^^^^^^^^^^^^^^^^^^^^^^^^^^
  File "C:\Users\azizo\Desktop\Pathnio1\backend\env\Lib\site-packages\django\db\models\query.py", line 91, in __iter__
    results = compiler.execute_sql(
        chunked_fetch=self.chunked_fetch, chunk_size=self.chunk_size
    )
  File "C:\Users\azizo\Desktop\Pathnio1\backend\env\Lib\site-packages\django\db\models\sql\compiler.py", line 1623, in execute_sql
    cursor.execute(sql, params)
    ~~~~~~~~~~~~~~^^^^^^^^^^^^^
  File "C:\Users\azizo\Desktop\Pathnio1\backend\env\Lib\site-packages\django\db\backends\utils.py", line 122, in execute
    return super().execute(sql, params)
           ~~~~~~~~~~~~~~~^^^^^^^^^^^^^
  File "C:\Users\azizo\Desktop\Pathnio1\backend\env\Lib\site-packages\django\db\backends\utils.py", line 79, in execute
    return self._execute_with_wrappers(
           ~~~~~~~~~~~~~~~~~~~~~~~~~~~^
        sql, params, many=False, executor=self._execute
        ^^^^^^^^^^^^^^^^^^^^^^^^^^^^^^^^^^^^^^^^^^^^^^^
    )
    ^
  File "C:\Users\azizo\Desktop\Pathnio1\backend\env\Lib\site-packages\django\db\backends\utils.py", line 92, in _execute_with_wrappers
    return executor(sql, params, many, context)
  File "C:\Users\azizo\Desktop\Pathnio1\backend\env\Lib\site-packages\django\db\backends\utils.py", line 100, in _execute
    with self.db.wrap_database_errors:
         ^^^^^^^^^^^^^^^^^^^^^^^^^^^^
  File "C:\Users\azizo\Desktop\Pathnio1\backend\env\Lib\site-packages\django\db\utils.py", line 91, in __exit__
    raise dj_exc_value.with_traceback(traceback) from exc_value
  File "C:\Users\azizo\Desktop\Pathnio1\backend\env\Lib\site-packages\django\db\backends\utils.py", line 105, in _execute
    return self.cursor.execute(sql, params)
           ~~~~~~~~~~~~~~~~~~~^^^^^^^^^^^^^
  File "C:\Users\azizo\Desktop\Pathnio1\backend\env\Lib\site-packages\django\db\backends\sqlite3\base.py", line 360, in execute
    return super().execute(query, params)
           ~~~~~~~~~~~~~~~^^^^^^^^^^^^^^^
django.db.utils.OperationalError: no such table: accounts_profile
ERROR 2025-07-31 09:42:51,434 basehttp 1748 15400 "GET /api/accounts/users/all/ HTTP/1.1" 500 183258
ERROR 2025-07-31 09:42:51,576 log 1748 15400 Internal Server Error: /api/accounts/users/all/
Traceback (most recent call last):
  File "C:\Users\azizo\Desktop\Pathnio1\backend\env\Lib\site-packages\django\db\models\fields\related_descriptors.py", line 516, in __get__
    rel_obj = self.related.get_cached_value(instance)
  File "C:\Users\azizo\Desktop\Pathnio1\backend\env\Lib\site-packages\django\db\models\fields\mixins.py", line 37, in get_cached_value
    return instance._state.fields_cache[self.cache_name]
           ~~~~~~~~~~~~~~~~~~~~~~~~~~~~^^^^^^^^^^^^^^^^^
KeyError: 'profile'

During handling of the above exception, another exception occurred:

Traceback (most recent call last):
  File "C:\Users\azizo\Desktop\Pathnio1\backend\env\Lib\site-packages\django\db\backends\utils.py", line 105, in _execute
    return self.cursor.execute(sql, params)
           ~~~~~~~~~~~~~~~~~~~^^^^^^^^^^^^^
  File "C:\Users\azizo\Desktop\Pathnio1\backend\env\Lib\site-packages\django\db\backends\sqlite3\base.py", line 360, in execute
    return super().execute(query, params)
           ~~~~~~~~~~~~~~~^^^^^^^^^^^^^^^
sqlite3.OperationalError: no such table: accounts_profile

The above exception was the direct cause of the following exception:

Traceback (most recent call last):
  File "C:\Users\azizo\Desktop\Pathnio1\backend\env\Lib\site-packages\django\core\handlers\exception.py", line 55, in inner
    response = get_response(request)
  File "C:\Users\azizo\Desktop\Pathnio1\backend\env\Lib\site-packages\django\core\handlers\base.py", line 197, in _get_response
    response = wrapped_callback(request, *callback_args, **callback_kwargs)
  File "C:\Users\azizo\Desktop\Pathnio1\backend\env\Lib\site-packages\django\views\decorators\csrf.py", line 65, in _view_wrapper
    return view_func(request, *args, **kwargs)
  File "C:\Users\azizo\Desktop\Pathnio1\backend\env\Lib\site-packages\django\views\generic\base.py", line 105, in view
    return self.dispatch(request, *args, **kwargs)
           ~~~~~~~~~~~~~^^^^^^^^^^^^^^^^^^^^^^^^^^
  File "C:\Users\azizo\Desktop\Pathnio1\backend\env\Lib\site-packages\rest_framework\views.py", line 515, in dispatch
    response = self.handle_exception(exc)
  File "C:\Users\azizo\Desktop\Pathnio1\backend\env\Lib\site-packages\rest_framework\views.py", line 475, in handle_exception
    self.raise_uncaught_exception(exc)
    ~~~~~~~~~~~~~~~~~~~~~~~~~~~~~^^^^^
  File "C:\Users\azizo\Desktop\Pathnio1\backend\env\Lib\site-packages\rest_framework\views.py", line 486, in raise_uncaught_exception
    raise exc
  File "C:\Users\azizo\Desktop\Pathnio1\backend\env\Lib\site-packages\rest_framework\views.py", line 512, in dispatch
    response = handler(request, *args, **kwargs)
  File "C:\Users\azizo\Desktop\Pathnio1\backend\accounts\views.py", line 810, in get
    'profile_photo': u.profile.profile_photo.url if hasattr(u, 'profile') and u.profile.profile_photo else (company.profile_photo.url if company and company.profile_photo else None),
                                                    ~~~~~~~^^^^^^^^^^^^^^
  File "C:\Users\azizo\Desktop\Pathnio1\backend\env\Lib\site-packages\django\db\models\fields\related_descriptors.py", line 523, in __get__
    rel_obj = self.get_queryset(instance=instance).get(**filter_args)
  File "C:\Users\azizo\Desktop\Pathnio1\backend\env\Lib\site-packages\django\db\models\query.py", line 629, in get
    num = len(clone)
  File "C:\Users\azizo\Desktop\Pathnio1\backend\env\Lib\site-packages\django\db\models\query.py", line 366, in __len__
    self._fetch_all()
    ~~~~~~~~~~~~~~~^^
  File "C:\Users\azizo\Desktop\Pathnio1\backend\env\Lib\site-packages\django\db\models\query.py", line 1949, in _fetch_all
    self._result_cache = list(self._iterable_class(self))
                         ~~~~^^^^^^^^^^^^^^^^^^^^^^^^^^^^
  File "C:\Users\azizo\Desktop\Pathnio1\backend\env\Lib\site-packages\django\db\models\query.py", line 91, in __iter__
    results = compiler.execute_sql(
        chunked_fetch=self.chunked_fetch, chunk_size=self.chunk_size
    )
  File "C:\Users\azizo\Desktop\Pathnio1\backend\env\Lib\site-packages\django\db\models\sql\compiler.py", line 1623, in execute_sql
    cursor.execute(sql, params)
    ~~~~~~~~~~~~~~^^^^^^^^^^^^^
  File "C:\Users\azizo\Desktop\Pathnio1\backend\env\Lib\site-packages\django\db\backends\utils.py", line 122, in execute
    return super().execute(sql, params)
           ~~~~~~~~~~~~~~~^^^^^^^^^^^^^
  File "C:\Users\azizo\Desktop\Pathnio1\backend\env\Lib\site-packages\django\db\backends\utils.py", line 79, in execute
    return self._execute_with_wrappers(
           ~~~~~~~~~~~~~~~~~~~~~~~~~~~^
        sql, params, many=False, executor=self._execute
        ^^^^^^^^^^^^^^^^^^^^^^^^^^^^^^^^^^^^^^^^^^^^^^^
    )
    ^
  File "C:\Users\azizo\Desktop\Pathnio1\backend\env\Lib\site-packages\django\db\backends\utils.py", line 92, in _execute_with_wrappers
    return executor(sql, params, many, context)
  File "C:\Users\azizo\Desktop\Pathnio1\backend\env\Lib\site-packages\django\db\backends\utils.py", line 100, in _execute
    with self.db.wrap_database_errors:
         ^^^^^^^^^^^^^^^^^^^^^^^^^^^^
  File "C:\Users\azizo\Desktop\Pathnio1\backend\env\Lib\site-packages\django\db\utils.py", line 91, in __exit__
    raise dj_exc_value.with_traceback(traceback) from exc_value
  File "C:\Users\azizo\Desktop\Pathnio1\backend\env\Lib\site-packages\django\db\backends\utils.py", line 105, in _execute
    return self.cursor.execute(sql, params)
           ~~~~~~~~~~~~~~~~~~~^^^^^^^^^^^^^
  File "C:\Users\azizo\Desktop\Pathnio1\backend\env\Lib\site-packages\django\db\backends\sqlite3\base.py", line 360, in execute
    return super().execute(query, params)
           ~~~~~~~~~~~~~~~^^^^^^^^^^^^^^^
django.db.utils.OperationalError: no such table: accounts_profile
ERROR 2025-07-31 09:42:51,590 basehttp 1748 15400 "GET /api/accounts/users/all/ HTTP/1.1" 500 183258
ERROR 2025-07-31 09:44:54,200 log 1748 22944 Internal Server Error: /api/accounts/users/all/
Traceback (most recent call last):
  File "C:\Users\azizo\Desktop\Pathnio1\backend\env\Lib\site-packages\django\db\models\fields\related_descriptors.py", line 516, in __get__
    rel_obj = self.related.get_cached_value(instance)
  File "C:\Users\azizo\Desktop\Pathnio1\backend\env\Lib\site-packages\django\db\models\fields\mixins.py", line 37, in get_cached_value
    return instance._state.fields_cache[self.cache_name]
           ~~~~~~~~~~~~~~~~~~~~~~~~~~~~^^^^^^^^^^^^^^^^^
KeyError: 'profile'

During handling of the above exception, another exception occurred:

Traceback (most recent call last):
  File "C:\Users\azizo\Desktop\Pathnio1\backend\env\Lib\site-packages\django\db\backends\utils.py", line 105, in _execute
    return self.cursor.execute(sql, params)
           ~~~~~~~~~~~~~~~~~~~^^^^^^^^^^^^^
  File "C:\Users\azizo\Desktop\Pathnio1\backend\env\Lib\site-packages\django\db\backends\sqlite3\base.py", line 360, in execute
    return super().execute(query, params)
           ~~~~~~~~~~~~~~~^^^^^^^^^^^^^^^
sqlite3.OperationalError: no such table: accounts_profile

The above exception was the direct cause of the following exception:

Traceback (most recent call last):
  File "C:\Users\azizo\Desktop\Pathnio1\backend\env\Lib\site-packages\django\core\handlers\exception.py", line 55, in inner
    response = get_response(request)
  File "C:\Users\azizo\Desktop\Pathnio1\backend\env\Lib\site-packages\django\core\handlers\base.py", line 197, in _get_response
    response = wrapped_callback(request, *callback_args, **callback_kwargs)
  File "C:\Users\azizo\Desktop\Pathnio1\backend\env\Lib\site-packages\django\views\decorators\csrf.py", line 65, in _view_wrapper
    return view_func(request, *args, **kwargs)
  File "C:\Users\azizo\Desktop\Pathnio1\backend\env\Lib\site-packages\django\views\generic\base.py", line 105, in view
    return self.dispatch(request, *args, **kwargs)
           ~~~~~~~~~~~~~^^^^^^^^^^^^^^^^^^^^^^^^^^
  File "C:\Users\azizo\Desktop\Pathnio1\backend\env\Lib\site-packages\rest_framework\views.py", line 515, in dispatch
    response = self.handle_exception(exc)
  File "C:\Users\azizo\Desktop\Pathnio1\backend\env\Lib\site-packages\rest_framework\views.py", line 475, in handle_exception
    self.raise_uncaught_exception(exc)
    ~~~~~~~~~~~~~~~~~~~~~~~~~~~~~^^^^^
  File "C:\Users\azizo\Desktop\Pathnio1\backend\env\Lib\site-packages\rest_framework\views.py", line 486, in raise_uncaught_exception
    raise exc
  File "C:\Users\azizo\Desktop\Pathnio1\backend\env\Lib\site-packages\rest_framework\views.py", line 512, in dispatch
    response = handler(request, *args, **kwargs)
  File "C:\Users\azizo\Desktop\Pathnio1\backend\accounts\views.py", line 810, in get
    'profile_photo': u.profile.profile_photo.url if hasattr(u, 'profile') and u.profile.profile_photo else (company.profile_photo.url if company and company.profile_photo else None),
                                                    ~~~~~~~^^^^^^^^^^^^^^
  File "C:\Users\azizo\Desktop\Pathnio1\backend\env\Lib\site-packages\django\db\models\fields\related_descriptors.py", line 523, in __get__
    rel_obj = self.get_queryset(instance=instance).get(**filter_args)
  File "C:\Users\azizo\Desktop\Pathnio1\backend\env\Lib\site-packages\django\db\models\query.py", line 629, in get
    num = len(clone)
  File "C:\Users\azizo\Desktop\Pathnio1\backend\env\Lib\site-packages\django\db\models\query.py", line 366, in __len__
    self._fetch_all()
    ~~~~~~~~~~~~~~~^^
  File "C:\Users\azizo\Desktop\Pathnio1\backend\env\Lib\site-packages\django\db\models\query.py", line 1949, in _fetch_all
    self._result_cache = list(self._iterable_class(self))
                         ~~~~^^^^^^^^^^^^^^^^^^^^^^^^^^^^
  File "C:\Users\azizo\Desktop\Pathnio1\backend\env\Lib\site-packages\django\db\models\query.py", line 91, in __iter__
    results = compiler.execute_sql(
        chunked_fetch=self.chunked_fetch, chunk_size=self.chunk_size
    )
  File "C:\Users\azizo\Desktop\Pathnio1\backend\env\Lib\site-packages\django\db\models\sql\compiler.py", line 1623, in execute_sql
    cursor.execute(sql, params)
    ~~~~~~~~~~~~~~^^^^^^^^^^^^^
  File "C:\Users\azizo\Desktop\Pathnio1\backend\env\Lib\site-packages\django\db\backends\utils.py", line 122, in execute
    return super().execute(sql, params)
           ~~~~~~~~~~~~~~~^^^^^^^^^^^^^
  File "C:\Users\azizo\Desktop\Pathnio1\backend\env\Lib\site-packages\django\db\backends\utils.py", line 79, in execute
    return self._execute_with_wrappers(
           ~~~~~~~~~~~~~~~~~~~~~~~~~~~^
        sql, params, many=False, executor=self._execute
        ^^^^^^^^^^^^^^^^^^^^^^^^^^^^^^^^^^^^^^^^^^^^^^^
    )
    ^
  File "C:\Users\azizo\Desktop\Pathnio1\backend\env\Lib\site-packages\django\db\backends\utils.py", line 92, in _execute_with_wrappers
    return executor(sql, params, many, context)
  File "C:\Users\azizo\Desktop\Pathnio1\backend\env\Lib\site-packages\django\db\backends\utils.py", line 100, in _execute
    with self.db.wrap_database_errors:
         ^^^^^^^^^^^^^^^^^^^^^^^^^^^^
  File "C:\Users\azizo\Desktop\Pathnio1\backend\env\Lib\site-packages\django\db\utils.py", line 91, in __exit__
    raise dj_exc_value.with_traceback(traceback) from exc_value
  File "C:\Users\azizo\Desktop\Pathnio1\backend\env\Lib\site-packages\django\db\backends\utils.py", line 105, in _execute
    return self.cursor.execute(sql, params)
           ~~~~~~~~~~~~~~~~~~~^^^^^^^^^^^^^
  File "C:\Users\azizo\Desktop\Pathnio1\backend\env\Lib\site-packages\django\db\backends\sqlite3\base.py", line 360, in execute
    return super().execute(query, params)
           ~~~~~~~~~~~~~~~^^^^^^^^^^^^^^^
django.db.utils.OperationalError: no such table: accounts_profile
ERROR 2025-07-31 09:44:54,223 basehttp 1748 22944 "GET /api/accounts/users/all/ HTTP/1.1" 500 183258
ERROR 2025-07-31 09:44:58,388 log 1748 22944 Internal Server Error: /api/accounts/users/all/
Traceback (most recent call last):
  File "C:\Users\azizo\Desktop\Pathnio1\backend\env\Lib\site-packages\django\db\models\fields\related_descriptors.py", line 516, in __get__
    rel_obj = self.related.get_cached_value(instance)
  File "C:\Users\azizo\Desktop\Pathnio1\backend\env\Lib\site-packages\django\db\models\fields\mixins.py", line 37, in get_cached_value
    return instance._state.fields_cache[self.cache_name]
           ~~~~~~~~~~~~~~~~~~~~~~~~~~~~^^^^^^^^^^^^^^^^^
KeyError: 'profile'

During handling of the above exception, another exception occurred:

Traceback (most recent call last):
  File "C:\Users\azizo\Desktop\Pathnio1\backend\env\Lib\site-packages\django\db\backends\utils.py", line 105, in _execute
    return self.cursor.execute(sql, params)
           ~~~~~~~~~~~~~~~~~~~^^^^^^^^^^^^^
  File "C:\Users\azizo\Desktop\Pathnio1\backend\env\Lib\site-packages\django\db\backends\sqlite3\base.py", line 360, in execute
    return super().execute(query, params)
           ~~~~~~~~~~~~~~~^^^^^^^^^^^^^^^
sqlite3.OperationalError: no such table: accounts_profile

The above exception was the direct cause of the following exception:

Traceback (most recent call last):
  File "C:\Users\azizo\Desktop\Pathnio1\backend\env\Lib\site-packages\django\core\handlers\exception.py", line 55, in inner
    response = get_response(request)
  File "C:\Users\azizo\Desktop\Pathnio1\backend\env\Lib\site-packages\django\core\handlers\base.py", line 197, in _get_response
    response = wrapped_callback(request, *callback_args, **callback_kwargs)
  File "C:\Users\azizo\Desktop\Pathnio1\backend\env\Lib\site-packages\django\views\decorators\csrf.py", line 65, in _view_wrapper
    return view_func(request, *args, **kwargs)
  File "C:\Users\azizo\Desktop\Pathnio1\backend\env\Lib\site-packages\django\views\generic\base.py", line 105, in view
    return self.dispatch(request, *args, **kwargs)
           ~~~~~~~~~~~~~^^^^^^^^^^^^^^^^^^^^^^^^^^
  File "C:\Users\azizo\Desktop\Pathnio1\backend\env\Lib\site-packages\rest_framework\views.py", line 515, in dispatch
    response = self.handle_exception(exc)
  File "C:\Users\azizo\Desktop\Pathnio1\backend\env\Lib\site-packages\rest_framework\views.py", line 475, in handle_exception
    self.raise_uncaught_exception(exc)
    ~~~~~~~~~~~~~~~~~~~~~~~~~~~~~^^^^^
  File "C:\Users\azizo\Desktop\Pathnio1\backend\env\Lib\site-packages\rest_framework\views.py", line 486, in raise_uncaught_exception
    raise exc
  File "C:\Users\azizo\Desktop\Pathnio1\backend\env\Lib\site-packages\rest_framework\views.py", line 512, in dispatch
    response = handler(request, *args, **kwargs)
  File "C:\Users\azizo\Desktop\Pathnio1\backend\accounts\views.py", line 810, in get
    'profile_photo': u.profile.profile_photo.url if hasattr(u, 'profile') and u.profile.profile_photo else (company.profile_photo.url if company and company.profile_photo else None),
                                                    ~~~~~~~^^^^^^^^^^^^^^
  File "C:\Users\azizo\Desktop\Pathnio1\backend\env\Lib\site-packages\django\db\models\fields\related_descriptors.py", line 523, in __get__
    rel_obj = self.get_queryset(instance=instance).get(**filter_args)
  File "C:\Users\azizo\Desktop\Pathnio1\backend\env\Lib\site-packages\django\db\models\query.py", line 629, in get
    num = len(clone)
  File "C:\Users\azizo\Desktop\Pathnio1\backend\env\Lib\site-packages\django\db\models\query.py", line 366, in __len__
    self._fetch_all()
    ~~~~~~~~~~~~~~~^^
  File "C:\Users\azizo\Desktop\Pathnio1\backend\env\Lib\site-packages\django\db\models\query.py", line 1949, in _fetch_all
    self._result_cache = list(self._iterable_class(self))
                         ~~~~^^^^^^^^^^^^^^^^^^^^^^^^^^^^
  File "C:\Users\azizo\Desktop\Pathnio1\backend\env\Lib\site-packages\django\db\models\query.py", line 91, in __iter__
    results = compiler.execute_sql(
        chunked_fetch=self.chunked_fetch, chunk_size=self.chunk_size
    )
  File "C:\Users\azizo\Desktop\Pathnio1\backend\env\Lib\site-packages\django\db\models\sql\compiler.py", line 1623, in execute_sql
    cursor.execute(sql, params)
    ~~~~~~~~~~~~~~^^^^^^^^^^^^^
  File "C:\Users\azizo\Desktop\Pathnio1\backend\env\Lib\site-packages\django\db\backends\utils.py", line 122, in execute
    return super().execute(sql, params)
           ~~~~~~~~~~~~~~~^^^^^^^^^^^^^
  File "C:\Users\azizo\Desktop\Pathnio1\backend\env\Lib\site-packages\django\db\backends\utils.py", line 79, in execute
    return self._execute_with_wrappers(
           ~~~~~~~~~~~~~~~~~~~~~~~~~~~^
        sql, params, many=False, executor=self._execute
        ^^^^^^^^^^^^^^^^^^^^^^^^^^^^^^^^^^^^^^^^^^^^^^^
    )
    ^
  File "C:\Users\azizo\Desktop\Pathnio1\backend\env\Lib\site-packages\django\db\backends\utils.py", line 92, in _execute_with_wrappers
    return executor(sql, params, many, context)
  File "C:\Users\azizo\Desktop\Pathnio1\backend\env\Lib\site-packages\django\db\backends\utils.py", line 100, in _execute
    with self.db.wrap_database_errors:
         ^^^^^^^^^^^^^^^^^^^^^^^^^^^^
  File "C:\Users\azizo\Desktop\Pathnio1\backend\env\Lib\site-packages\django\db\utils.py", line 91, in __exit__
    raise dj_exc_value.with_traceback(traceback) from exc_value
  File "C:\Users\azizo\Desktop\Pathnio1\backend\env\Lib\site-packages\django\db\backends\utils.py", line 105, in _execute
    return self.cursor.execute(sql, params)
           ~~~~~~~~~~~~~~~~~~~^^^^^^^^^^^^^
  File "C:\Users\azizo\Desktop\Pathnio1\backend\env\Lib\site-packages\django\db\backends\sqlite3\base.py", line 360, in execute
    return super().execute(query, params)
           ~~~~~~~~~~~~~~~^^^^^^^^^^^^^^^
django.db.utils.OperationalError: no such table: accounts_profile
ERROR 2025-07-31 09:44:58,426 basehttp 1748 22944 "GET /api/accounts/users/all/ HTTP/1.1" 500 183258
ERROR 2025-07-31 09:45:17,339 log 1748 14976 Internal Server Error: /api/accounts/users/all/
Traceback (most recent call last):
  File "C:\Users\azizo\Desktop\Pathnio1\backend\env\Lib\site-packages\django\db\models\fields\related_descriptors.py", line 516, in __get__
    rel_obj = self.related.get_cached_value(instance)
  File "C:\Users\azizo\Desktop\Pathnio1\backend\env\Lib\site-packages\django\db\models\fields\mixins.py", line 37, in get_cached_value
    return instance._state.fields_cache[self.cache_name]
           ~~~~~~~~~~~~~~~~~~~~~~~~~~~~^^^^^^^^^^^^^^^^^
KeyError: 'profile'

During handling of the above exception, another exception occurred:

Traceback (most recent call last):
  File "C:\Users\azizo\Desktop\Pathnio1\backend\env\Lib\site-packages\django\db\backends\utils.py", line 105, in _execute
    return self.cursor.execute(sql, params)
           ~~~~~~~~~~~~~~~~~~~^^^^^^^^^^^^^
  File "C:\Users\azizo\Desktop\Pathnio1\backend\env\Lib\site-packages\django\db\backends\sqlite3\base.py", line 360, in execute
    return super().execute(query, params)
           ~~~~~~~~~~~~~~~^^^^^^^^^^^^^^^
sqlite3.OperationalError: no such table: accounts_profile

The above exception was the direct cause of the following exception:

Traceback (most recent call last):
  File "C:\Users\azizo\Desktop\Pathnio1\backend\env\Lib\site-packages\django\core\handlers\exception.py", line 55, in inner
    response = get_response(request)
  File "C:\Users\azizo\Desktop\Pathnio1\backend\env\Lib\site-packages\django\core\handlers\base.py", line 197, in _get_response
    response = wrapped_callback(request, *callback_args, **callback_kwargs)
  File "C:\Users\azizo\Desktop\Pathnio1\backend\env\Lib\site-packages\django\views\decorators\csrf.py", line 65, in _view_wrapper
    return view_func(request, *args, **kwargs)
  File "C:\Users\azizo\Desktop\Pathnio1\backend\env\Lib\site-packages\django\views\generic\base.py", line 105, in view
    return self.dispatch(request, *args, **kwargs)
           ~~~~~~~~~~~~~^^^^^^^^^^^^^^^^^^^^^^^^^^
  File "C:\Users\azizo\Desktop\Pathnio1\backend\env\Lib\site-packages\rest_framework\views.py", line 515, in dispatch
    response = self.handle_exception(exc)
  File "C:\Users\azizo\Desktop\Pathnio1\backend\env\Lib\site-packages\rest_framework\views.py", line 475, in handle_exception
    self.raise_uncaught_exception(exc)
    ~~~~~~~~~~~~~~~~~~~~~~~~~~~~~^^^^^
  File "C:\Users\azizo\Desktop\Pathnio1\backend\env\Lib\site-packages\rest_framework\views.py", line 486, in raise_uncaught_exception
    raise exc
  File "C:\Users\azizo\Desktop\Pathnio1\backend\env\Lib\site-packages\rest_framework\views.py", line 512, in dispatch
    response = handler(request, *args, **kwargs)
  File "C:\Users\azizo\Desktop\Pathnio1\backend\accounts\views.py", line 810, in get
    'profile_photo': u.profile.profile_photo.url if hasattr(u, 'profile') and u.profile.profile_photo else (company.profile_photo.url if company and company.profile_photo else None),
                                                    ~~~~~~~^^^^^^^^^^^^^^
  File "C:\Users\azizo\Desktop\Pathnio1\backend\env\Lib\site-packages\django\db\models\fields\related_descriptors.py", line 523, in __get__
    rel_obj = self.get_queryset(instance=instance).get(**filter_args)
  File "C:\Users\azizo\Desktop\Pathnio1\backend\env\Lib\site-packages\django\db\models\query.py", line 629, in get
    num = len(clone)
  File "C:\Users\azizo\Desktop\Pathnio1\backend\env\Lib\site-packages\django\db\models\query.py", line 366, in __len__
    self._fetch_all()
    ~~~~~~~~~~~~~~~^^
  File "C:\Users\azizo\Desktop\Pathnio1\backend\env\Lib\site-packages\django\db\models\query.py", line 1949, in _fetch_all
    self._result_cache = list(self._iterable_class(self))
                         ~~~~^^^^^^^^^^^^^^^^^^^^^^^^^^^^
  File "C:\Users\azizo\Desktop\Pathnio1\backend\env\Lib\site-packages\django\db\models\query.py", line 91, in __iter__
    results = compiler.execute_sql(
        chunked_fetch=self.chunked_fetch, chunk_size=self.chunk_size
    )
  File "C:\Users\azizo\Desktop\Pathnio1\backend\env\Lib\site-packages\django\db\models\sql\compiler.py", line 1623, in execute_sql
    cursor.execute(sql, params)
    ~~~~~~~~~~~~~~^^^^^^^^^^^^^
  File "C:\Users\azizo\Desktop\Pathnio1\backend\env\Lib\site-packages\django\db\backends\utils.py", line 122, in execute
    return super().execute(sql, params)
           ~~~~~~~~~~~~~~~^^^^^^^^^^^^^
  File "C:\Users\azizo\Desktop\Pathnio1\backend\env\Lib\site-packages\django\db\backends\utils.py", line 79, in execute
    return self._execute_with_wrappers(
           ~~~~~~~~~~~~~~~~~~~~~~~~~~~^
        sql, params, many=False, executor=self._execute
        ^^^^^^^^^^^^^^^^^^^^^^^^^^^^^^^^^^^^^^^^^^^^^^^
    )
    ^
  File "C:\Users\azizo\Desktop\Pathnio1\backend\env\Lib\site-packages\django\db\backends\utils.py", line 92, in _execute_with_wrappers
    return executor(sql, params, many, context)
  File "C:\Users\azizo\Desktop\Pathnio1\backend\env\Lib\site-packages\django\db\backends\utils.py", line 100, in _execute
    with self.db.wrap_database_errors:
         ^^^^^^^^^^^^^^^^^^^^^^^^^^^^
  File "C:\Users\azizo\Desktop\Pathnio1\backend\env\Lib\site-packages\django\db\utils.py", line 91, in __exit__
    raise dj_exc_value.with_traceback(traceback) from exc_value
  File "C:\Users\azizo\Desktop\Pathnio1\backend\env\Lib\site-packages\django\db\backends\utils.py", line 105, in _execute
    return self.cursor.execute(sql, params)
           ~~~~~~~~~~~~~~~~~~~^^^^^^^^^^^^^
  File "C:\Users\azizo\Desktop\Pathnio1\backend\env\Lib\site-packages\django\db\backends\sqlite3\base.py", line 360, in execute
    return super().execute(query, params)
           ~~~~~~~~~~~~~~~^^^^^^^^^^^^^^^
django.db.utils.OperationalError: no such table: accounts_profile
ERROR 2025-07-31 09:45:17,354 basehttp 1748 14976 "GET /api/accounts/users/all/ HTTP/1.1" 500 183258
ERROR 2025-07-31 09:45:17,582 log 1748 2192 Internal Server Error: /api/accounts/users/all/
Traceback (most recent call last):
  File "C:\Users\azizo\Desktop\Pathnio1\backend\env\Lib\site-packages\django\db\models\fields\related_descriptors.py", line 516, in __get__
    rel_obj = self.related.get_cached_value(instance)
  File "C:\Users\azizo\Desktop\Pathnio1\backend\env\Lib\site-packages\django\db\models\fields\mixins.py", line 37, in get_cached_value
    return instance._state.fields_cache[self.cache_name]
           ~~~~~~~~~~~~~~~~~~~~~~~~~~~~^^^^^^^^^^^^^^^^^
KeyError: 'profile'

During handling of the above exception, another exception occurred:

Traceback (most recent call last):
  File "C:\Users\azizo\Desktop\Pathnio1\backend\env\Lib\site-packages\django\db\backends\utils.py", line 105, in _execute
    return self.cursor.execute(sql, params)
           ~~~~~~~~~~~~~~~~~~~^^^^^^^^^^^^^
  File "C:\Users\azizo\Desktop\Pathnio1\backend\env\Lib\site-packages\django\db\backends\sqlite3\base.py", line 360, in execute
    return super().execute(query, params)
           ~~~~~~~~~~~~~~~^^^^^^^^^^^^^^^
sqlite3.OperationalError: no such table: accounts_profile

The above exception was the direct cause of the following exception:

Traceback (most recent call last):
  File "C:\Users\azizo\Desktop\Pathnio1\backend\env\Lib\site-packages\django\core\handlers\exception.py", line 55, in inner
    response = get_response(request)
  File "C:\Users\azizo\Desktop\Pathnio1\backend\env\Lib\site-packages\django\core\handlers\base.py", line 197, in _get_response
    response = wrapped_callback(request, *callback_args, **callback_kwargs)
  File "C:\Users\azizo\Desktop\Pathnio1\backend\env\Lib\site-packages\django\views\decorators\csrf.py", line 65, in _view_wrapper
    return view_func(request, *args, **kwargs)
  File "C:\Users\azizo\Desktop\Pathnio1\backend\env\Lib\site-packages\django\views\generic\base.py", line 105, in view
    return self.dispatch(request, *args, **kwargs)
           ~~~~~~~~~~~~~^^^^^^^^^^^^^^^^^^^^^^^^^^
  File "C:\Users\azizo\Desktop\Pathnio1\backend\env\Lib\site-packages\rest_framework\views.py", line 515, in dispatch
    response = self.handle_exception(exc)
  File "C:\Users\azizo\Desktop\Pathnio1\backend\env\Lib\site-packages\rest_framework\views.py", line 475, in handle_exception
    self.raise_uncaught_exception(exc)
    ~~~~~~~~~~~~~~~~~~~~~~~~~~~~~^^^^^
  File "C:\Users\azizo\Desktop\Pathnio1\backend\env\Lib\site-packages\rest_framework\views.py", line 486, in raise_uncaught_exception
    raise exc
  File "C:\Users\azizo\Desktop\Pathnio1\backend\env\Lib\site-packages\rest_framework\views.py", line 512, in dispatch
    response = handler(request, *args, **kwargs)
  File "C:\Users\azizo\Desktop\Pathnio1\backend\accounts\views.py", line 810, in get
    'profile_photo': u.profile.profile_photo.url if hasattr(u, 'profile') and u.profile.profile_photo else (company.profile_photo.url if company and company.profile_photo else None),
                                                    ~~~~~~~^^^^^^^^^^^^^^
  File "C:\Users\azizo\Desktop\Pathnio1\backend\env\Lib\site-packages\django\db\models\fields\related_descriptors.py", line 523, in __get__
    rel_obj = self.get_queryset(instance=instance).get(**filter_args)
  File "C:\Users\azizo\Desktop\Pathnio1\backend\env\Lib\site-packages\django\db\models\query.py", line 629, in get
    num = len(clone)
  File "C:\Users\azizo\Desktop\Pathnio1\backend\env\Lib\site-packages\django\db\models\query.py", line 366, in __len__
    self._fetch_all()
    ~~~~~~~~~~~~~~~^^
  File "C:\Users\azizo\Desktop\Pathnio1\backend\env\Lib\site-packages\django\db\models\query.py", line 1949, in _fetch_all
    self._result_cache = list(self._iterable_class(self))
                         ~~~~^^^^^^^^^^^^^^^^^^^^^^^^^^^^
  File "C:\Users\azizo\Desktop\Pathnio1\backend\env\Lib\site-packages\django\db\models\query.py", line 91, in __iter__
    results = compiler.execute_sql(
        chunked_fetch=self.chunked_fetch, chunk_size=self.chunk_size
    )
  File "C:\Users\azizo\Desktop\Pathnio1\backend\env\Lib\site-packages\django\db\models\sql\compiler.py", line 1623, in execute_sql
    cursor.execute(sql, params)
    ~~~~~~~~~~~~~~^^^^^^^^^^^^^
  File "C:\Users\azizo\Desktop\Pathnio1\backend\env\Lib\site-packages\django\db\backends\utils.py", line 122, in execute
    return super().execute(sql, params)
           ~~~~~~~~~~~~~~~^^^^^^^^^^^^^
  File "C:\Users\azizo\Desktop\Pathnio1\backend\env\Lib\site-packages\django\db\backends\utils.py", line 79, in execute
    return self._execute_with_wrappers(
           ~~~~~~~~~~~~~~~~~~~~~~~~~~~^
        sql, params, many=False, executor=self._execute
        ^^^^^^^^^^^^^^^^^^^^^^^^^^^^^^^^^^^^^^^^^^^^^^^
    )
    ^
  File "C:\Users\azizo\Desktop\Pathnio1\backend\env\Lib\site-packages\django\db\backends\utils.py", line 92, in _execute_with_wrappers
    return executor(sql, params, many, context)
  File "C:\Users\azizo\Desktop\Pathnio1\backend\env\Lib\site-packages\django\db\backends\utils.py", line 100, in _execute
    with self.db.wrap_database_errors:
         ^^^^^^^^^^^^^^^^^^^^^^^^^^^^
  File "C:\Users\azizo\Desktop\Pathnio1\backend\env\Lib\site-packages\django\db\utils.py", line 91, in __exit__
    raise dj_exc_value.with_traceback(traceback) from exc_value
  File "C:\Users\azizo\Desktop\Pathnio1\backend\env\Lib\site-packages\django\db\backends\utils.py", line 105, in _execute
    return self.cursor.execute(sql, params)
           ~~~~~~~~~~~~~~~~~~~^^^^^^^^^^^^^
  File "C:\Users\azizo\Desktop\Pathnio1\backend\env\Lib\site-packages\django\db\backends\sqlite3\base.py", line 360, in execute
    return super().execute(query, params)
           ~~~~~~~~~~~~~~~^^^^^^^^^^^^^^^
django.db.utils.OperationalError: no such table: accounts_profile
ERROR 2025-07-31 09:45:17,844 basehttp 1748 2192 "GET /api/accounts/users/all/ HTTP/1.1" 500 183258
